Workbook

Sheet GRÁFICO

Sheet BALANÇO
B2: Balanço
B3: MÊS | C3: FATURADO | D3: LUCRO | E3: CUSTO | F3: RECEBERÁ | G3: PAGARÁ | H3: PAGO | I3: RECEBIDO
B4: JANEIRO | C4: =JANEIRO!D64 -> 9265.25 | D4: =JANEIRO!D65 -> 6404.25 | E4: =JANEIRO!D66 -> 2861 | F4: =JANEIRO!D67 -> 0 | G4: =JANEIRO!D68 -> 0 | H4: =JANEIRO!D69 -> 2861 | I4: =JANEIRO!D70 -> 6404.25
B5: FEVEREIRO | C5: =FEVEREIRO!D112 -> 21209.25 | D5: =FEVEREIRO!D113 -> 12807.48 | E5: =FEVEREIRO!D114 -> 8401.77 | F5: =FEVEREIRO!D115 -> 0 | G5: =FEVEREIRO!D116 -> 0 | H5: =FEVEREIRO!D117 -> 8401.77 | I5: =FEVEREIRO!D118 -> 12807.48
B6: MARÇO | C6: =MARÇO!D112 -> 21608.56 | D6: =MARÇO!D113 -> 12704.9 | E6: =MARÇO!D114 -> 8903.66 | F6: =MARÇO!D115 -> 0 | G6: =MARÇO!D116 -> 0 | H6: =MARÇO!D117 -> 8903.66 | I6: =MARÇO!D118 -> 12704.9
B7: ABRIL | C7: =ABRIL!D118 -> 27399.38 | D7: =ABRIL!D119 -> 16233 | E7: =ABRIL!D120 -> 11166.38 | F7: =ABRIL!D121 -> 0 | G7: =ABRIL!D122 -> 0 | H7: =ABRIL!D123 -> 11166.38 | I7: =ABRIL!D124 -> 16233
B8: MAIO | C8: =MAIO!D121 -> 24879.47 | D8: =MAIO!D122 -> 15081.64 | E8: =MAIO!D123 -> 9797.83 | F8: =MAIO!D124 -> 0 | G8: =MAIO!D125 -> 0 | H8: =MAIO!D126 -> 9797.83 | I8: =MAIO!D127 -> 15081.64
B9: JUNHO | C9: =JUNHO!D182 -> 37820.12 | D9: =JUNHO!D183 -> 22316.3 | E9: =JUNHO!D184 -> 15503.82 | F9: =JUNHO!D185 -> 0 | G9: =JUNHO!D186 -> 0 | H9: =JUNHO!D187 -> 15503.82 | I9: =JUNHO!D188 -> 22316.3
B10: JULHO | C10: =JULHO!D198 -> 39452.25 | D10: =JULHO!D199 -> 23719.95 | E10: =JULHO!D200 -> 15732.3 | F10: =JULHO!D201 -> 0 | G10: =JULHO!D202 -> 0 | H10: =JULHO!D203 -> 15732.3 | I10: =JULHO!D204 -> 23719.95
B11: AGOSTO | C11: =AGOSTO!D161 -> 26653.54 | D11: =AGOSTO!D162 -> 15493 | E11: =AGOSTO!D163 -> 11160.54 | F11: =AGOSTO!D164 -> 0 | G11: =AGOSTO!D165 -> 0 | H11: =AGOSTO!D166 -> 11160.54 | I11: =AGOSTO!D167 -> 15493
B12: SETEMBRO | C12: =SETEMBRO!D165 -> 28175.57 | D12: =SETEMBRO!D166 -> 15790 | E12: =SETEMBRO!D167 -> 12385.57 | F12: =SETEMBRO!D168 -> 0 | G12: =SETEMBRO!D169 -> 0 | H12: =SETEMBRO!D170 -> 12385.57 | I12: =SETEMBRO!D171 -> 15830
B13: OUTUBRO | C13: =OUTUBRO!D114 -> 24788 | D13: =OUTUBRO!D115 -> 14820.1 | E13: =OUTUBRO!D116 -> 9967.9 | F13: =OUTUBRO!D117 -> 0 | G13: =OUTUBRO!D118 -> 0 | H13: =OUTUBRO!D119 -> 9967.9 | I13: =OUTUBRO!D120 -> 14820.1
B14: NOVEMBRO | C14: =NOVEMBRO!D148 -> 27363.64 | D14: =NOVEMBRO!D149 -> 12294.57 | E14: =NOVEMBRO!D150 -> 15069.07 | F14: =NOVEMBRO!D151 -> 3310 | G14: =NOVEMBRO!D152 -> 6180.95 | H14: =NOVEMBRO!D153 -> 8888.12 | I14: =NOVEMBRO!D154 -> 8984.57
B15: DEZEMBRO | C15: =DEZEMBRO!D75 -> 1950 | D15: =DEZEMBRO!D76 -> 1200 | E15: =DEZEMBRO!D77 -> 750 | F15: =DEZEMBRO!D78 -> 1200 | G15: =DEZEMBRO!D79 -> 750 | H15: =DEZEMBRO!D80 -> 0 | I15: =DEZEMBRO!D81 -> 0
B16: TOTAL | C16: =SUM(C4:C15) -> 290565.03 | D16: =SUM(D4:D15) -> 168865.19 | E16: =SUM(E4:E15) -> 121699.84 | F16: =SUM(F4:F15) -> 4510 | G16: =SUM(G4:G15) -> 6930.95 | H16: =SUM(H4:H15) -> 114768.89 | I16: =SUM(I4:I15) -> 164395.19

Sheet JANEIRO
B2: CONTROLE DE DILIGÊNCIAS
B4: SOLICITAÇÃO | C4: Nº. DOC9 | D4: SOLICITANTE | E4: TEL. | F4: TIPO DE DILIGÊNCIA | G4: Processo | H4: DATA | I4: HORA | J4: LOCAL | K4: Cidade - UF | L4: VALOR | M4: DATA PAG | N4: PAGAM. | O4: CONTRATADO | P4: TEL. 2 | Q4: CUSTO | R4: PRAZO | S4: PAGO | T4: STATUS | U4: LUCRO
B5: 45665 | D5: Ana Flavia Tanimoto | E5: 16 99783-4544 | F5: Procotolo | H5: 45666 | L5: 150 | N5: CUMPRIDO | S5: SIM | T5: CUMPRIDO | U5: =Table_2[[#This Row],[VALOR]]-Table_2[[#This Row],[ CUSTO]] -> 150
B6: 45672 | D6: Letícia | E6: 11 94925-2506 | F6: Procotolo | H6: 45672 | J6: Prefeitura Municipal | K6: Canarana/MT | L6: 300 | N6: CUMPRIDO | O6: Geiciany Alencar | P6: 65 9207-4899 | Q6: 150 | S6: SIM | T6: CUMPRIDO | U6: =Table_2[[#This Row],[VALOR]]-Table_2[[#This Row],[ CUSTO]] -> 150
B7: 45673 | D7: Jessica | E7: 41 9685-0539 | F7: Acompanhamento | H7: 45677 | I7: 0.41666667 | J7: Marques de São Vicente | K7: São Paulo - SP | L7: 400 | N7: CUMPRIDO | O7: Diligência Própria | S7: SIM | T7: CUMPRIDO | U7: =Table_2[[#This Row],[VALOR]]-Table_2[[#This Row],[ CUSTO]] -> 400
B8: 45663 | D8: Cláudia Maxxi | E8: 11 99113-8935 | F8: Instrução - Presencial | G8: 0011051.24.2024.5.15.0131 | H8: 45678 | I8: 0.49305556 | J8: 12ª | K8: CAMPINAS - SP | N8: CUMPRIDO | O8: Patricia Von Ah | P8: 19 99155-8565 | Q8: 50 | S8: SIM | T8: CUMPRIDO | U8: =Table_2[[#This Row],[VALOR]]-Table_2[[#This Row],[ CUSTO]] -> -50
B9: 45663 | D9: Cláudia Maxxi | E9: 11 99113-8935 | F9: Una - Presencial | G9: 1000765-56.2024.5.02.0381 | H9: 45678 | I9: 0.35416667 | J9: 1ª | K9: OSASCO - SP | L9: 200 | N9: CUMPRIDO | O9: Joao Tomaz da Silva | P9: 11 97377-8980 | Q9: 70 | S9: SIM | T9: CUMPRIDO | U9: =Table_2[[#This Row],[VALOR]]-Table_2[[#This Row],[ CUSTO]] -> 130
B10: 45672 | D10: Vivian Barbosa | E10: 11 94569-1656 | F10: Audiência UNA | H10: 45678 | I10: 0.58680556 | J10: 10ª Vara do Trabalho | K10: CAMPINAS - SP | L10: 150 | M10: 45726 | N10: CUMPRIDO | O10: Miriam Pinatto Gehring | P10: 19 99220-3513 | Q10: 70 | S10: SIM | T10: CUMPRIDO | U10: =Table_2[[#This Row],[VALOR]]-Table_2[[#This Row],[ CUSTO]] -> 80
B11: 45677 | D11: Mayara | E11: 12 98170-8541 | F11: Procotolo | H11: 45678 | J11: Prefeitura Municipal | K11: Balneário Piçarras - SP | U11: =Table_2[[#This Row],[VALOR]]-Table_2[[#This Row],[ CUSTO]] -> 0
B12: 45663 | D12: Cláudia Maxxi | E12: 11 99113-8935 | F12: Una - Presencial | G12: 0010932-51.2024.5.15.0038 | H12: 45679 | I12: 0.44444444 | J12: Única | K12: BRAGANÇA PAULISTA - SP | L12: 200 | N12: CUMPRIDO | O12: Patricia Von Ah | P12: 19 99155-8565 | Q12: 70 | R12: ok | S12: SIM | T12: CUMPRIDO | U12: =Table_2[[#This Row],[VALOR]]-Table_2[[#This Row],[ CUSTO]] -> 130
B13: 45673 | D13: Andrezza | E13: 62 8268-9720 | F13: Audiência de Conciliação | H13: 45679 | I13: 0.375 | J13: Departamento de Defesa do Consumidor | K13: Atibaia - SP | L13: 150 | N13: CUMPRIDO | O13: Patricia Von Ah | P13: 19 99155-8565 | Q13: 50 | S13: SIM | T13: CUMPRIDO | U13: =Table_2[[#This Row],[VALOR]]-Table_2[[#This Row],[ CUSTO]] -> 100
B14: 45677 | D14: Dalila Passos | E14: 11 94535-7095 | F14: Audiência | G14: 1001623-52.2024.5.02.0231 | H14: 45679 | I14: 0.38541667 | J14: 1ª | K14: Carapicuíba - SP | L14: 150 | N14: CUMPRIDO | O14: Camila Roncalle | P14: 11 98992-0599 | Q14: 70 | S14: SIM | T14: CUMPRIDO | U14: =Table_2[[#This Row],[VALOR]]-Table_2[[#This Row],[ CUSTO]] -> 80
B15: 45678 | D15: Henriette Brigagão | E15: 35 9215-0702 | F15: Audiência | H15: 45679 | I15: 0.57638889 | J15: 2ª | K15: Suzano - SP | L15: 200 | N15: CUMPRIDO | O15: Fernando Santos | P15: 11 98307-2224 | Q15: 70 | S15: SIM | T15: CUMPRIDO | U15: =Table_2[[#This Row],[VALOR]]-Table_2[[#This Row],[ CUSTO]] -> 130
B16: 45679 | D16: Thiago Coriolano | E16: 11 98775-8123 | F16: Audiência | H16: 45679 | I16: 0.40625 | J16: 9ª | K16: Guarulhos - SP | L16: 200 | N16: CUMPRIDO | O16: Andréia Marques | P16: 11 98815-9490 | Q16: 80 | S16: SIM | T16: CUMPRIDO | U16: =Table_2[[#This Row],[VALOR]]-Table_2[[#This Row],[ CUSTO]] -> 120
B17: 45666 | D17: MTO ADVOGADOS | E17: 31 8107-6333 | F17: Audiência Cível | H17: 45680 | I17: 0.64583333 | J17: Juizado Especial Cível | K17: Santo André - SP | L17: 200 | N17: CUMPRIDO | O17: Raquel Farias Amaral | P17: 11 91914-1798 | Q17: 70 | S17: SIM | T17: CUMPRIDO | U17: =Table_2[[#This Row],[VALOR]]-Table_2[[#This Row],[ CUSTO]] -> 130
B18: 45678 | D18: Jessica | E18: 41 9685-0539 | F18: Acompanhamento | H18: 45680 | I18: 0.58333333 | J18: Marques de São Vicente | K18: São Paulo - SP | L18: =300+36.8 -> 336.8 | N18: CUMPRIDO | O18: Diligência Própria | Q18: 36.8 | S18: SIM | T18: CUMPRIDO | U18: =Table_2[[#This Row],[VALOR]]-Table_2[[#This Row],[ CUSTO]] -> 300
B19: 45678 | D19: Lucas Mançano | E19: 61 9143-8757 | F19: Una - Presencial | G19: 1001852-71.2024.5.02.0373 | H19: 45680 | I19: 0.59375 | J19: 3ª | K19: Mogi das Cruzes - SP | L19: 400 | N19: CUMPRIDO | O19: Tamara Batiston Ferreira | P19: 11 97638-4161 | Q19: 120 | S19: SIM | T19: CUMPRIDO | U19: =Table_2[[#This Row],[VALOR]]-Table_2[[#This Row],[ CUSTO]] -> 280
B20: 45644 | D20: LACOSTA ADVOGADOS | E20: 21 95922-4000 / 11 91039-6920 | F20: Audiência | H20: 45681 | I20: 0.35416667 | J20: 34ª Vara do Trabalho da Barra Funda | K20: São Paulo - SP | L20: 150 | N20: CUMPRIDO | O20: Joao Tomaz da Silva | P20: 11 97377-8980 | Q20: 70 | S20: SIM | T20: CUMPRIDO | U20: =Table_2[[#This Row],[VALOR]]-Table_2[[#This Row],[ CUSTO]] -> 80
B21: 45671 | D21: Marina Demenciano | E21: 19 99438-7420 | F21: Audiência UNA | G21: 1001889-78.2024.5.02.0024 | H21: 45681 | I21: 0.38194444 | J21: 24ª Vara do Trabalho da Barra Funda | K21: São Paulo - SP | L21: 200 | M21: 45693 | N21: CUMPRIDO | O21: Rafael Fernandes Capelas Yamakami | P21: 11 99939-8419 | Q21: 70 | S21: SIM | T21: CUMPRIDO | U21: =Table_2[[#This Row],[VALOR]]-Table_2[[#This Row],[ CUSTO]] -> 130
B22: 45681 | D22: Jessica | E22: 41 9685-0539 | F22: Coleta de Assinaturas | H22: 45682 | I22: 0.58333333 | K22: São Paulo - SP | L22: 536.8 | N22: CUMPRIDO | O22: Diligência Própria | Q22: 36.8 | S22: SIM | T22: CUMPRIDO | U22: =Table_2[[#This Row],[VALOR]]-Table_2[[#This Row],[ CUSTO]] -> 500
B23: 45644 | D23: LACOSTA ADVOGADOS | E23: 21 95922-4000 / 11 91039-6920 | F23: Audiência | H23: 45684 | I23: 0.66666667 | J23: 66ª Vara do Trabalho da Barra Funda | K23: São Paulo - SP | L23: 150 | N23: CUMPRIDO | O23: Joao Tomaz da Silva | P23: 11 97377-8980 | Q23: 70 | S23: SIM | T23: CUMPRIDO | U23: =Table_2[[#This Row],[VALOR]]-Table_2[[#This Row],[ CUSTO]] -> 80
B24: 45663 | D24: Cláudia Maxxi | E24: 11 99113-8935 | F24: Instrução - Presencial | G24: 1001604-18.2023.5.02.0381 | H24: 45684 | I24: 0.375 | J24: 1ª | K24: OSASCO - SP | L24: 200 | M24: 45688 | N24: CUMPRIDO | O24: Joao Tomaz da Silva | P24: 11 97377-8980 | Q24: 70 | S24: SIM | T24: CUMPRIDO | U24: =Table_2[[#This Row],[VALOR]]-Table_2[[#This Row],[ CUSTO]] -> 130
B25: 45671 | D25: Marina Demenciano | E25: 19 99438-7420 | F25: Audiência UNA | G25: 1001856-14.2024.5.02.0081 | H25: 45684 | I25: 0.56944444 | J25: 81ª Vara do Trabalho da Barra Funda | K25: São Paulo - SP | L25: 200 | M25: 45693 | N25: CUMPRIDO | O25: Joao Tomaz da Silva | P25: 11 97377-8980 | Q25: 70 | S25: SIM | T25: CUMPRIDO | U25: =Table_2[[#This Row],[VALOR]]-Table_2[[#This Row],[ CUSTO]] -> 130
B26: 45681 | D26: Beatriz Aragão & Bernardo | E26: 85 3252-2939 - 85 8405-1478 | F26: Audiência UNA | G26: 1001776-94.2024.5.02.0713 | H26: 45684 | I26: 0.5625 | J26: 88ª da Barra Funda | K26: São Paulo - SP | L26: 200 | N26: CUMPRIDO | O26: Amanda Pivott | P26: 11 94857-0549 | Q26: 70 | S26: SIM | T26: CUMPRIDO | U26: =Table_2[[#This Row],[VALOR]]-Table_2[[#This Row],[ CUSTO]] -> 130
B27: 45681 | C27: 4636037 | D27: DOC9 | F27: Audiência UNA | G27: 1001814-59.2024.5.02.0373 | H27: 45684 | I27: 0.63194444 | J27: 3ª | K27: Mogi das Cruzes - SP | L27: 84.25 | M27: 45703 | N27: CUMPRIDO | O27: Diligência Própria | S27: SIM | T27: CUMPRIDO | U27: =Table_2[[#This Row],[VALOR]]-Table_2[[#This Row],[ CUSTO]] -> 84.25
B28: 45681 | D28: Gabriel Belarmino | E28: 11 98863-8637 | F28: Despacho | G28: 1013171-35.2023.4.06.3803 | H28: 45684 | J28: 3ª Vara Federal | K28: Uberlândia - MG | L28: 250 | N28: CUMPRIDO | O28: Gabriela Viana | P28: 34 9135-5994 | Q28: 70 | S28: SIM | T28: CUMPRIDO | U28: =Table_2[[#This Row],[VALOR]]-Table_2[[#This Row],[ CUSTO]] -> 180
B29: 45684 | D29: Thiago Coriolano | E29: 11 98775-8123 | F29: Procotolo | H29: 45684 | K29: Taubaté - SP | L29: 180 | N29: CUMPRIDO | O29: Tamyres Fim | P29: 12 99181-8165 | Q29: 40 | S29: SIM | T29: CUMPRIDO | U29: =Table_2[[#This Row],[VALOR]]-Table_2[[#This Row],[ CUSTO]] -> 140
B30: 45660 | D30: Leticia Prado | E30: 11 94744-8723 | F30: Audiência Cível | H30: 45685 | I30: 0.64583333 | J30: Juizado Especial Cível | K30: Suzano - SP | L30: 120 | N30: CUMPRIDO | O30: Diligência Própria | S30: SIM | T30: CUMPRIDO | U30: =Table_2[[#This Row],[VALOR]]-Table_2[[#This Row],[ CUSTO]] -> 120
B31: 45663 | D31: Cláudia Maxxi | E31: 11 99113-8935 | F31: Instrução - Presencial | G31: 0011218-81.2023.5.15.0032 | H31: 45685 | I31: 0.66319444 | J31: 10ª | K31: CAMPINAS - SP | L31: 200 | M31: 45688 | N31: CUMPRIDO | O31: Patricia Von Ah | P31: 19 99155-8565 | Q31: 50 | R31: ok | S31: SIM | T31: CUMPRIDO | U31: =Table_2[[#This Row],[VALOR]]-Table_2[[#This Row],[ CUSTO]] -> 150
B32: 45671 | D32: Marina Demenciano | E32: 19 99438-7420 | F32: Audiência UNA | G32: 1001857-12.2024.5.02.0012 | H32: 45685 | I32: 0.39583333 | J32: 12ª Vara do Trabalho da Barra Funda | K32: São Paulo - SP | L32: 200 | M32: 45693 | N32: CUMPRIDO | O32: Joao Tomaz da Silva | P32: 11 97377-8980 | Q32: 70 | S32: SIM | T32: CUMPRIDO | U32: =Table_2[[#This Row],[VALOR]]-Table_2[[#This Row],[ CUSTO]] -> 130
B33: 45674 | D33: Josiane | E33: 45 9979-5193 | F33: Conciliação | G33: 1032551-94.2024.8.26.0577 | H33: 45685 | I33: 0.47916667 | J33: 1ª Vara do Juizado Especial Cível | K33: SÃO JOSE DOS CAMPOS - SP | L33: 120 | N33: CUMPRIDO | O33: Helena Do Amaral Simionelli | P33: 12 99108-0694 | Q33: 70 | S33: SIM | T33: CUMPRIDO | U33: =Table_2[[#This Row],[VALOR]]-Table_2[[#This Row],[ CUSTO]] -> 50
B34: 45681 | D34: Nathalia Fett Advogados | E34: 51 9114-0718 | F34: Audiência UNA | G34: 0020751-10.2024.5.04.0752 | H34: 45685 | I34: 0.4375 | J34: 2ª | K34: Santa Rosa - RS | L34: 200 | M34: 45688 | N34: CUMPRIDO | O34: Eliane Andréia Andreski | P34: 55 9910-8804 | Q34: 120 | S34: SIM | T34: CUMPRIDO | U34: =Table_2[[#This Row],[VALOR]]-Table_2[[#This Row],[ CUSTO]] -> 80
B35: 45684 | D35: Cláudia Maxxi | E35: 11 99113-8935 | F35: Instrução - Presencial | G35: 0011879-65.2023.5.15.0095 | H35: 45685 | I35: 0.44444444 | J35: 8ª | K35: CAMPINAS - SP | M35: perdeu | O35: Patricia Von Ah | P35: 19 99155-8565 | T35: CUMPRIDO | U35: =Table_2[[#This Row],[VALOR]]-Table_2[[#This Row],[ CUSTO]] -> 0
B36: 45685 | D36: Cláudia Maxxi | E36: 11 99113-8935 | F36: Instrução - Presencial | G36: 0010473.67.2024.5.15.0129 | H36: 45685 | I36: 0.36458333 | J36: 10ª | K36: CAMPINAS - SP | L36: 200 | M36: 45688 | N36: CUMPRIDO | O36: Patricia Von Ah | P36: 19 99155-8565 | Q36: 80 | S36: SIM | T36: CUMPRIDO | U36: =Table_2[[#This Row],[VALOR]]-Table_2[[#This Row],[ CUSTO]] -> 120
B37: 45663 | D37: Cláudia Maxxi | E37: 11 99113-8935 | F37: Instrução -Presencial | G37: 0010259-70.2024.5.15.0131 | H37: 45686 | I37: 0.53472222 | J37: 12ª | K37: CAMPINAS - SP | M37: 45688 | N37: CUMPRIDO | O37: Patricia Von Ah | P37: 19 99155-8565 | Q37: 50 | R37: ok | S37: SIM | T37: CUMPRIDO | U37: =Table_2[[#This Row],[VALOR]]-Table_2[[#This Row],[ CUSTO]] -> -50
B38: 45663 | D38: Cláudia Maxxi | E38: 11 99113-8935 | F38: Una - Presencial | G38: 0010467-98.2024.5.15.0084 | H38: 45686 | I38: 0.59722222 | J38: 4ª | K38: SÃO JOSE DOS CAMPOS - SP | L38: 200 | M38: 45688 | N38: CUMPRIDO | O38: Helena Do Amaral Simionelli | P38: 12 99108-0694 | Q38: 50 | S38: SIM | T38: CUMPRIDO | U38: =Table_2[[#This Row],[VALOR]]-Table_2[[#This Row],[ CUSTO]] -> 150
B39: 45681 | D39: Vivian Barbosa | E39: 11 94569-1656 | F39: Despacho | G39: 0011091-74.2023.5.15.0152 | H39: 45686 | J39: Vara do Trabalho | K39: Hortolândia - SP | L39: 200 | M39: 45726 | N39: CUMPRIDO | O39: Anna Asahara | P39: 19 97408-8344 | Q39: 50 | S39: SIM | T39: CUMPRIDO | U39: =Table_2[[#This Row],[VALOR]]-Table_2[[#This Row],[ CUSTO]] -> 150
B40: 45681 | D40: Vivian Barbosa | E40: 11 94569-1656 | F40: Instrução -Presencial | G40: 0001491-58.2024.5.09.0670 | H40: 45686 | I40: 0.44444444 | J40: 1ª | K40: São José dos Pinhais - PR | L40: 300 | M40: 45726 | N40: CUMPRIDO | O40: Katia Sousa | P40: 41 9155-8251 | Q40: 120 | S40: SIM | T40: CUMPRIDO | U40: =Table_2[[#This Row],[VALOR]]-Table_2[[#This Row],[ CUSTO]] -> 180
B41: 45681 | D41: Vivian Barbosa | E41: 11 94569-1656 | F41: Instrução -Presencial | G41: 0011171-07.2024.5.15.0054 | H41: 45686 | I41: 0.61458333 | J41: 1ª | K41: Sertãozinho - SP | L41: 450 | M41: 45726 | N41: CUMPRIDO | O41: Lídia Maria Nascimento Alves da Silva | P41: 16 99401-0695 | Q41: 200 | S41: SIM | T41: CUMPRIDO | U41: =Table_2[[#This Row],[VALOR]]-Table_2[[#This Row],[ CUSTO]] -> 250
B42: 45681 | D42: Vivian Barbosa | E42: 11 94569-1656 | F42: Instrução -Presencial | G42: 0010337-02.2024.5.15.0087 | H42: 45686 | I42: 0.65972222 | J42: 1ª | K42: Paulínia - SP | L42: 300 | M42: 45726 | N42: CUMPRIDO | O42: Andréia Manzini | P42: 19 99452-9159 | Q42: 80 | S42: SIM | T42: CUMPRIDO | U42: =Table_2[[#This Row],[VALOR]]-Table_2[[#This Row],[ CUSTO]] -> 220
...

Sheet FEVEREIRO
B2: CONTROLE DE DILIGÊNCIAS
B4: SOLICITAÇÃO | C4: Nº. DOC9 | D4: SOLICITANTE | E4: TEL. | F4: TIPO DE DILIGÊNCIA | G4: Processo | H4: DATA | I4: HORA | J4: LOCAL | K4: Cidade - UF | L4: VALOR | M4: DATA PAG | N4: PAGAM. | O4: CONTRATADO | P4: TEL. 2 | Q4: CUSTO | R4: PRAZO | S4: PAGO | T4: STATUS | U4: LUCRO
B5: 45685 | D5: Cláudia Maxxi | E5: 11 99113-8935 | F5: Una-Presencial | G5: 0010465-31.2024.5.15.0084 | H5: 45691 | I5: 0.5625 | J5: 4ª | K5: SÃO JOSE DOS CAMPOS | L5: 200 | N5: CUMPRIDO | O5: Helena Do Amaral Simionelli | P5: 12 99108-0694 | Q5: 50 | S5: SIM | T5: CUMPRIDO | U5: =Table_3[[#This Row],[VALOR]]-Table_3[[#This Row],[ CUSTO]] -> 150
B6: 45688 | D6: Jessica | E6: 41 9685-0539 | F6: Coleta de Assinaturas | H6: 45691 | I6: 0.72916667 | K6: Bauru - SP | L6: 175 | N6: CUMPRIDO | O6: Lara Estahl Prieto | P6: 14 3218-2500 | Q6: 50 | S6: SIM | T6: CUMPRIDO | U6: =Table_3[[#This Row],[VALOR]]-Table_3[[#This Row],[ CUSTO]] -> 125
B7: 45691 | D7: Cláudia Maxxi | E7: 11 99113-8935 | F7: Instrução - Presencial | G7: 1000426-10.2024.5.02.0701 | H7: 45691 | I7: 0.64583333 | J7: 1ª Vara do Trabalho de São Paulo - Zona Sul | K7: São Paulo - SP | L7: 200 | N7: CUMPRIDO | O7: Israel Bessa | P7: Israel Bessa | Q7: 50 | S7: SIM | T7: CUMPRIDO | U7: =Table_3[[#This Row],[VALOR]]-Table_3[[#This Row],[ CUSTO]] -> 150
B8: 45670 | D8: José Mario Paula | E8: 11 96186-8989 | F8: Acompanhamento | H8: 45692 | I8: 0.41666667 | J8: 1ª Delegacia Territorial | K8: Serrinha - BA | L8: 300 | M8: 45327 | N8: CUMPRIDO | O8: Laryssa Campos | P8: 71 9664-8462 | Q8: 150 | S8: SIM | T8: CUMPRIDO | U8: =Table_3[[#This Row],[VALOR]]-Table_3[[#This Row],[ CUSTO]] -> 150
B9: 45685 | D9: Cláudia Maxxi | E9: 11 99113-8935 | F9: Instrução - Presencial | G9: 0010567-72.2024.5.15.0013 | H9: 45692 | I9: 0.41666667 | J9: 1ª | K9: SÃO JOSÉ DOS CAMPOS | L9: 200 | N9: CUMPRIDO | O9: Helena Do Amaral Simionelli | P9: 12 99108-0694 | Q9: 50 | S9: SIM | T9: CUMPRIDO | U9: =Table_3[[#This Row],[VALOR]]-Table_3[[#This Row],[ CUSTO]] -> 150
B10: 45685 | D10: LACOSTA ADVOGADOS | E10: 21 95922-4000 / 11 91039-6920 | F10: Audiência | H10: 45692 | I10: 0.61805556 | J10: 30ª da Barra Funda | K10: São Paulo - SP | L10: 150 | N10: CUMPRIDO | O10: Joao Tomaz da Silva | P10: 11 97377-8980 | Q10: 70 | S10: SIM | T10: CUMPRIDO | U10: =Table_3[[#This Row],[VALOR]]-Table_3[[#This Row],[ CUSTO]] -> 80
B11: 45687 | D11: Marina Demenciano | E11: 19 99438-7420 | F11: Una - Presencial | H11: 45692 | I11: 0.38541667 | J11: 18ª | K11: Rio de Janeiro - RJ | L11: 280 | N11: CUMPRIDO | O11: Franciely Maciel | P11: 21 95932-7919 | Q11: 140 | S11: SIM | T11: CUMPRIDO | U11: =Table_3[[#This Row],[VALOR]]-Table_3[[#This Row],[ CUSTO]] -> 140
B12: 45687 | D12: Marina Demenciano | E12: 19 99438-7420 | F12: Una - Presencial | H12: 45692 | I12: 0.41666667 | J12: 45ª da Barra Funda | K12: São Paulo - SP | L12: 200 | N12: CUMPRIDO | O12: Joao Tomaz da Silva | P12: 11 97377-8980 | Q12: 70 | S12: SIM | T12: CUMPRIDO | U12: =Table_3[[#This Row],[VALOR]]-Table_3[[#This Row],[ CUSTO]] -> 130
B13: 45687 | D13: Marina Demenciano | E13: 19 99438-7420 | F13: Una - Presencial | H13: 45692 | I13: 0.54861111 | J13: 36ª da Barra Funda | K13: São Paulo - SP | L13: 200 | N13: CUMPRIDO | O13: Joao Tomaz da Silva | P13: 11 97377-8980 | Q13: 70 | S13: SIM | T13: CUMPRIDO | U13: =Table_3[[#This Row],[VALOR]]-Table_3[[#This Row],[ CUSTO]] -> 130
B14: 45688 | D14: Jessica | E14: 41 9685-0539 | F14: Coleta de Assinaturas | G14: Valdevino | H14: 45692 | I14: 0.41666667 | K14: Joanópolis - SP | L14: 500 | N14: CUMPRIDO | O14: Maicon Paulo | P14: 11 97266-7939 | Q14: 125 | S14: SIM | T14: CUMPRIDO | U14: =Table_3[[#This Row],[VALOR]]-Table_3[[#This Row],[ CUSTO]] -> 375
B15: 45688 | D15: Nathalia Fett Advogados | E15: 51 9114-0718 | F15: Instrução - Presencial | G15: 0020720-31.2024.5.04.0124 | H15: 45692 | I15: 0.4375 | J15: 4ª Vara do Trabalho | K15: Rio Grande - RS | L15: 200 | N15: CUMPRIDO | O15: Gabriela Machado | P15: 53 9139-9707 | Q15: 100 | S15: SIM | T15: CUMPRIDO | U15: =Table_3[[#This Row],[VALOR]]-Table_3[[#This Row],[ CUSTO]] -> 100
B16: 45691 | D16: Cláudia Maxxi | E16: 11 99113-8935 | F16: Una - Presencial | G16: 1000734-17.2024.5.02.0064 | H16: 45692 | I16: 0.5625 | J16: 64ª da Barra Funda | K16: São Paulo - SP | L16: 200 | N16: CUMPRIDO | O16: Arlindo Felipe Jr | P16: 11 99635-2611 | Q16: 40 | S16: SIM | T16: CUMPRIDO | U16: =Table_3[[#This Row],[VALOR]]-Table_3[[#This Row],[ CUSTO]] -> 160
B17: 45691 | D17: Jessica | E17: 41 9685-0539 | F17: Coleta de Assinaturas | G17: VASCO LUIZ TEODORO | H17: 45692 | I17: 0.66666667 | J17: R PARANA, 1540, AP 502, BRASIL | K17: Uberlândia - MG | L17: 300 | N17: CUMPRIDO | O17: Gabriela Viana | P17: 34 9135-5994 | Q17: 100 | S17: SIM | T17: CUMPRIDO | U17: =Table_3[[#This Row],[VALOR]]-Table_3[[#This Row],[ CUSTO]] -> 200
B18: 45685 | D18: Cláudia Maxxi | E18: 11 99113-8935 | F18: Instrução -Presencial | G18: 0011706-47.2023.5.15.0093 | H18: 45693 | I18: 0.4375 | J18: 6ª | K18: CAMPINAS - SP | N18: CUMPRIDO | O18: Patricia Von Ah | P18: 19 99155-8565 | S18: SIM | T18: CUMPRIDO | U18: =Table_3[[#This Row],[VALOR]]-Table_3[[#This Row],[ CUSTO]] -> 0
B19: 45685 | D19: Cláudia Maxxi | E19: 11 99113-8935 | F19: Instrução - Presencial | G19: 0012034-45.2023.5.15.0038 | H19: 45693 | I19: 0.61111111 | J19: ÚNICA | K19: BRAGANÇA PAULISTA | L19: 200 | N19: CUMPRIDO | O19: Patricia Von Ah | P19: 19 99155-8565 | Q19: 70 | S19: SIM | T19: CUMPRIDO | U19: =Table_3[[#This Row],[VALOR]]-Table_3[[#This Row],[ CUSTO]] -> 130
B20: 45685 | D20: Cláudia Maxxi | E20: 11 99113-8935 | F20: Instrução - Presencial | G20: 0012064-80.2023.5.15.0038 | H20: 45693 | I20: 0.63194444 | J20: ÚNICA | K20: BRAGANÇA PAULISTA | L20: 200 | N20: CUMPRIDO | O20: Patricia Von Ah | P20: 19 99155-8565 | Q20: 70 | S20: SIM | T20: CUMPRIDO | U20: =Table_3[[#This Row],[VALOR]]-Table_3[[#This Row],[ CUSTO]] -> 130
B21: 45687 | D21: Vivian Barbosa | E21: 11 94569-1656 | F21: Inicial | G21: 0001724-47.2024.5.10.0017 | H21: 45693 | I21: 0.37222222 | J21: 17ª | K21: Brasília - DF | L21: 250 | M21: 45726 | N21: CUMPRIDO | O21: Luana Amancio | P21: 61 8542-3080 | Q21: 120 | S21: SIM | T21: CUMPRIDO | U21: =Table_3[[#This Row],[VALOR]]-Table_3[[#This Row],[ CUSTO]] -> 130
B22: 45691 | D22: Nathalia Fett Advogados | E22: 51 9114-0718 | F22: Una - Presencial | G22: 0021007-42.2024.5.04.0205 | H22: 45693 | I22: 0.375 | J22: Posto da Justiça do Trabalho | K22: Capão da Canoa - RS | L22: 250 | N22: CUMPRIDO | O22: Juliana Grundler | P22: 51 9592-0101 | Q22: 100 | S22: SIM | T22: CUMPRIDO | U22: =Table_3[[#This Row],[VALOR]]-Table_3[[#This Row],[ CUSTO]] -> 150
B23: 45686 | D23: Eliana Ivano | E23: 11 99442-6135 | F23: Instrução - Presencial | G23: 0011043-23.2024.5.15.0139 | H23: 45694 | I23: 0.64583333 | J23: Vara do Trabalho | K23: Ubatuba - SP | L23: 250 | N23: CUMPRIDO | O23: Glaydson Roberto | P23: 12 99795-5162 | Q23: 100 | S23: SIM | T23: CUMPRIDO | U23: =Table_3[[#This Row],[VALOR]]-Table_3[[#This Row],[ CUSTO]] -> 150
B24: 45688 | D24: Nathalia Fett Advogados | E24: 51 9114-0718 | F24: Una - Presencial | G24: 0011416-93.2024.5.03.0040 | H24: 45694 | I24: 0.36458333 | J24: 2ª Vara do Trabalho | K24: Sete Lagoas - MG | L24: 200 | N24: CUMPRIDO | O24: Lucia Helena de Azevedo Ribeiro | P24: 61 8168-3829 | Q24: 70 | S24: SIM | T24: CUMPRIDO | U24: =Table_3[[#This Row],[VALOR]]-Table_3[[#This Row],[ CUSTO]] -> 130
B25: 45688 | D25: Nathalia Fett Advogados | E25: 51 9114-0718 | F25: Instrução - Presencial | G25: 0020530-06.2024.5.04.0662 | H25: 45694 | I25: 0.59375 | J25: 2ª Vara do Trabalho | K25: Passo Fundo - RS | L25: 280 | N25: CUMPRIDO | O25: Cristian Paniz | P25: 54 9917-5166 | Q25: 150 | S25: SIM | T25: CUMPRIDO | U25: =Table_3[[#This Row],[VALOR]]-Table_3[[#This Row],[ CUSTO]] -> 130
B26: 45691 | D26: Nathalia Fett Advogados | E26: 51 9114-0718 | F26: Una - Presencial | G26: 0011212-45.2024.5.03.0009 | H26: 45694 | I26: 0.38819444 | J26: 9ª Vara do Trabalho | K26: Belo Horizonte - MG | L26: 200 | N26: CUMPRIDO | O26: Diogo Ribeiro Cassini | P26: 31 8722-3837 | Q26: 70 | S26: SIM | T26: CUMPRIDO | U26: =Table_3[[#This Row],[VALOR]]-Table_3[[#This Row],[ CUSTO]] -> 130
B27: 45693 | D27: Jessica | E27: 41 9685-0539 | F27: Coleta de Assinaturas | G27: ALFREDO DE SOUZA ALBERTO | H27: 45694 | I27: 0.58333333 | J27: Boqueirão | K27: Santos - SP | L27: =300+36.8 -> 336.8 | N27: CUMPRIDO | O27: IRB - Isabelle | P27: 13 98804-4390 | Q27: =75+36.8 -> 111.8 | S27: SIM | T27: CUMPRIDO | U27: =Table_3[[#This Row],[VALOR]]-Table_3[[#This Row],[ CUSTO]] -> 225
B28: 45693 | D28: Julia Berton | E28: 11 95106-8588 | F28: Una - Presencial | H28: 45694 | I28: 0.54166667 | J28: 2ª Vara do Trabalho | K28: Mogi das Cruzes - SP | L28: 200 | N28: CUMPRIDO | O28: Tamara Ferreira | P28: 11 97638-4161 | Q28: 70 | S28: SIM | T28: CUMPRIDO | U28: =Table_3[[#This Row],[VALOR]]-Table_3[[#This Row],[ CUSTO]] -> 130
B29: 45694 | D29: LACOSTA ADVOGADOS | E29: 21 95922-4000 / 11 91039-6920 | F29: Audiência | H29: 45694 | I29: 0.65972222 | J29: 7ª da Barra Funda | K29: São Paulo - SP | L29: 150 | N29: CUMPRIDO | O29: Ana Paula Santos | P29: 11 96195-3023 | Q29: 70 | S29: SIM | T29: CUMPRIDO | U29: =Table_3[[#This Row],[VALOR]]-Table_3[[#This Row],[ CUSTO]] -> 80
B30: 45687 | D30: Vivian Barbosa | E30: 11 94569-1656 | F30: Inicial | G30: 0011217-32.2024.5.15.0139 | H30: 45695 | I30: 0.39236111 | J30: Vara do Trabalho | K30: Ubatuba - SP | L30: 250 | M30: 45726 | N30: CUMPRIDO | O30: Glaydson Roberto | P30: 12 99795-5162 | Q30: 120 | S30: SIM | T30: CUMPRIDO | U30: =Table_3[[#This Row],[VALOR]]-Table_3[[#This Row],[ CUSTO]] -> 130
B31: 45694 | D31: Thiago Coriolano | E31: 11 98775-8123 | F31: Una - Presencial | G31: 1001810-31.2024.5.02.0467 | H31: 45695 | I31: 0.47222222 | J31: 7ª | K31: São Bernardo do Campo - SP | L31: 200 | N31: CUMPRIDO | O31: Elisangela ES - SOLUÇÕES JURÍDICAS | P31: 11 93067-5163 | Q31: 90 | S31: SIM | T31: CUMPRIDO | U31: =Table_3[[#This Row],[VALOR]]-Table_3[[#This Row],[ CUSTO]] -> 110
B32: 45694 | D32: Cláudia Maxxi | E32: 11 99113-8935 | F32: Baixa CTPS | H32: 45695 | I32: 0.45833333 | J32: Vara do Trabalho | K32: Indaiatuba - SP | L32: 150 | N32: CUMPRIDO | O32: Patricia Von Ah | P32: 19 99155-8565 | Q32: 80 | S32: SIM | T32: CUMPRIDO | U32: =Table_3[[#This Row],[VALOR]]-Table_3[[#This Row],[ CUSTO]] -> 70
B33: 45695 | D33: Marina Demenciano | E33: 19 99438-7420 | F33: Una - Presencial | G33: 1001003-74.2024.5.02.0446 | H33: 45698 | I33: 0.40277778 | J33: 6ª Vara do Trabalho | K33: Santos - SP | L33: 280 | N33: CUMPRIDO | O33: IRB - Isabelle | P33: 13 98804-4390 | Q33: 130 | S33: SIM | T33: CUMPRIDO | U33: =Table_3[[#This Row],[VALOR]]-Table_3[[#This Row],[ CUSTO]] -> 150
B34: 45686 | D34: Rebeca | E34: 19 99416-4309 | F34: Una - Presencial | H34: 45699 | I34: 0.36805556 | J34: 17ª da Barra Funda | K34: São Paulo - SP | L34: 150 | N34: CUMPRIDO | O34: Joao Tomaz da Silva | P34: 11 97377-8980 | Q34: 70 | S34: SIM | T34: CUMPRIDO | U34: =Table_3[[#This Row],[VALOR]]-Table_3[[#This Row],[ CUSTO]] -> 80
B35: 45693 | D35: Vivian Barbosa | E35: 11 94569-1656 | F35: Instrução - Presencial | G35: 0012224-51.2023.5.15.0153 | H35: 45699 | I35: 0.54166667 | J35: 6ª | K35: Ribeirão Preto - SP | L35: 400 | N35: CUMPRIDO | O35: Mayara Belfort | P35: 16 99138-1367 | Q35: 130 | S35: SIM | T35: CUMPRIDO | U35: =Table_3[[#This Row],[VALOR]]-Table_3[[#This Row],[ CUSTO]] -> 270
B36: 45694 | D36: Lucas Mançano | E36: 61 9143-8757 | F36: Una - Presencial | G36: 1000017-20.2025.5.02.0371 | H36: 45699 | I36: 0.40972222 | J36: 1ª | K36: Mogi das Cruzes - SP | L36: 250 | N36: CUMPRIDO | O36: Tamara Ferreira | P36: 11 97638-4161 | Q36: 80 | S36: SIM | T36: CUMPRIDO | U36: =Table_3[[#This Row],[VALOR]]-Table_3[[#This Row],[ CUSTO]] -> 170
B37: 45695 | D37: Jessica | E37: 41 9685-0539 | F37: Coleta de Assinaturas | G37: Mayle Martins Moreira | H37: 45699 | I37: 0.625 | J37: Rua Antônio de Albuquerque, n°330, Sala 901, Ed. Comercial Canopus Corporate, Savassi | K37: Belo Horizonte - MG | L37: =300+12.3 -> 312.3 | N37: CUMPRIDO | O37: Diogo Ribeiro Cassini | P37: 31 8722-3837 | Q37: =120+12.3 -> 132.3 | S37: SIM | T37: CUMPRIDO | U37: =Table_3[[#This Row],[VALOR]]-Table_3[[#This Row],[ CUSTO]] -> 180
B38: 45699 | D38: Jessica | E38: 41 9685-0539 | F38: Coleta de Assinaturas | G38: RONEL MARIANO | H38: 45699 | I38: 0.6875 | J38: Rua Doutor Euridice José Bento, nº 115, Bairro Jardim do Lago | K38: CAMPINAS - SP | L38: =300+36.8 -> 336.8 | N38: CUMPRIDO | O38: Camila Rodrigues | P38: 19 98405-2277 | Q38: =100+36.8 -> 136.8 | S38: SIM | T38: CUMPRIDO | U38: =Table_3[[#This Row],[VALOR]]-Table_3[[#This Row],[ CUSTO]] -> 200
B39: 45699 | D39: Cláudia Maxxi | E39: 11 99113-8935 | F39: Una - Presencial | G39: 1001836-39.2024.5.02.0011 | H39: 45699 | I39: 0.40625 | J39: 11ª | K39: São Paulo - SP | L39: 150 | N39: CUMPRIDO | O39: Ingrid Bellem | P39: 11 97375-7309 | Q39: 50 | S39: SIM | T39: CUMPRIDO | U39: =Table_3[[#This Row],[VALOR]]-Table_3[[#This Row],[ CUSTO]] -> 100
B40: 45699 | D40: Sofia - Benjamim Advogados | E40: 22 99978-0715 | F40: Despacho | G40: 1008513-60.2025.8.26.0002 | H40: 45699 | J40: 6ª Vara Cível de Santo Amaro | K40: São Paulo - SP | L40: 180 | N40: CUMPRIDO | O40: Sandra Natale | P40: 11 91313-7104 | Q40: 70 | S40: SIM | T40: CUMPRIDO | U40: =Table_3[[#This Row],[VALOR]]-Table_3[[#This Row],[ CUSTO]] -> 110
B41: 45694 | D41: LACOSTA ADVOGADOS | E41: 21 95922-4000 / 11 91039-6920 | F41: Audiência | H41: 45700 | I41: 0.39583333 | J41: 27ª da Barra Funda | K41: São Paulo - SP | L41: 250 | N41: CUMPRIDO | O41: Ingrid Bellem | P41: 11 97375-7309 | Q41: 120 | S41: SIM | T41: CUMPRIDO | U41: =Table_3[[#This Row],[VALOR]]-Table_3[[#This Row],[ CUSTO]] -> 130
B42: 45697 | D42: Eliana Ivano | E42: 11 99442-6135 | F42: Instrução - Presencial | H42: 45700 | I42: 0.60416667 | J42: Vara do Trabalho | K42: Mogi Mirim - SP | L42: 250 | N42: CUMPRIDO | O42: Daiane Ferreira Gomes | P42: 19 98172-7578 | Q42: 150 | S42: SIM | T42: CUMPRIDO | U42: =Table_3[[#This Row],[VALOR]]-Table_3[[#This Row],[ CUSTO]] -> 100
...

Sheet MARÇO
B2: CONTROLE DE DILIGÊNCIAS
B4: SOLICITAÇÃO | C4: Nº. DOC9 | D4: SOLICITANTE | E4: TEL. | F4: TIPO DE DILIGÊNCIA | G4: Processo | H4: DATA | I4: HORA | J4: LOCAL | K4: Cidade - UF | L4: VALOR | M4: DATA PAG | N4: PAGAM. | O4: CONTRATADO | P4: TEL. 2 | Q4: CUSTO | R4: PRAZO | S4: PAGO | T4: STATUS | U4: LUCRO
B5: 45685 | D5: LACOSTA ADVOGADOS | E5: 21 95922-4000 / 11 91039-6920 | F5: Audiência | H5: 45722 | I5: 0.39583333 | J5: 90ª da Barra Funda | K5: São Paulo - SP | L5: 150 | N5: CUMPRIDO | O5: Joao Tomaz da Silva | P5: 11 97377-8980 | Q5: 70 | S5: SIM | T5: CUMPRIDO | U5: =Table_4[[#This Row],[VALOR]]-Table_4[[#This Row],[ CUSTO]] -> 80
B6: 45712 | D6: LACOSTA ADVOGADOS | E6: 21 95922-4000 / 11 91039-6920 | F6: Audiência | H6: 45722 | I6: 0.58333333 | J6: 29ª da Barra Funda | K6: São Paulo - SP | L6: 150 | N6: CUMPRIDO | O6: Joao Tomaz da Silva | P6: 11 97377-8980 | Q6: 70 | S6: SIM | T6: CUMPRIDO | U6: =Table_4[[#This Row],[VALOR]]-Table_4[[#This Row],[ CUSTO]] -> 80
B7: 45712 | D7: LACOSTA ADVOGADOS | E7: 21 95922-4000 / 11 91039-6920 | F7: Audiência | H7: 45734 | I7: 0.55208333 | J7: 64ª da Barra Funda | K7: São Paulo - SP | L7: 150 | N7: CUMPRIDO | O7: Joao Tomaz da Silva | P7: 11 97377-8980 | Q7: 70 | S7: SIM | T7: CUMPRIDO | U7: =Table_4[[#This Row],[VALOR]]-Table_4[[#This Row],[ CUSTO]] -> 80
B8: 45712 | D8: LACOSTA ADVOGADOS | E8: 21 95922-4000 / 11 91039-6920 | F8: Audiência | H8: 45734 | I8: 0.53472222 | J8: 14ª da Zona Leste | K8: São Paulo - SP | L8: 150 | N8: CUMPRIDO | O8: Elisangela ES - SOLUÇÕES JURÍDICAS | P8: 11 93067-5163 | Q8: 80 | S8: SIM | T8: CUMPRIDO | U8: =Table_4[[#This Row],[VALOR]]-Table_4[[#This Row],[ CUSTO]] -> 70
B9: 45712 | D9: LACOSTA ADVOGADOS | E9: 21 95922-4000 / 11 91039-6920 | F9: Audiência | H9: 45742 | I9: 0.5625 | J9: 14ª da Barra Funda | K9: São Paulo - SP | L9: 150 | N9: CUMPRIDO | O9: Joao Tomaz da Silva | P9: 11 97377-8980 | Q9: 70 | S9: SIM | T9: CUMPRIDO | U9: =Table_4[[#This Row],[VALOR]]-Table_4[[#This Row],[ CUSTO]] -> 80
B10: 45712 | D10: LACOSTA ADVOGADOS | E10: 21 95922-4000 / 11 91039-6920 | F10: Audiência | H10: 45743 | I10: 0.39583333 | J10: 75ª da Barra Funda | K10: São Paulo - SP | L10: 150 | N10: CUMPRIDO | O10: Joao Tomaz da Silva | P10: 11 97377-8980 | Q10: 70 | S10: SIM | T10: CUMPRIDO | U10: =Table_4[[#This Row],[VALOR]]-Table_4[[#This Row],[ CUSTO]] -> 80
B11: 45714 | D11: Marília Martins | E11: 62 9410-5041 | F11: UNA - Presencial | H11: 45726 | I11: 0.48611111 | J11: 11ª Vara do Trabalho | K11: Guarulhos - SP | L11: 200 | N11: CUMPRIDO | O11: Alessandra Oliveira | P11: 11 99656-3238 | Q11: 80 | S11: SIM | T11: CUMPRIDO | U11: =Table_4[[#This Row],[VALOR]]-Table_4[[#This Row],[ CUSTO]] -> 120
B12: 45715 | D12: Jessica | E12: 41 9685-0539 | F12: Coleta de Assinaturas | G12: JOSÉ IVAN BEZERRA | H12: 45722 | I12: 0.41666667 | J12: Av. Dom Luís, 807 – 20º e 21º andar, Meireles | K12: Fortaleza - CE | L12: =300+91.6+4 -> 395.6 | M12: ok | N12: CUMPRIDO | O12: Gabriela Sousa | P12: 85 8640-0693 | Q12: =80+4+91.6 -> 175.6 | S12: SIM | T12: CUMPRIDO | U12: =Table_4[[#This Row],[VALOR]]-Table_4[[#This Row],[ CUSTO]] -> 220
B13: 45716 | D13: Jessica | E13: 41 9685-0539 | F13: Coleta de Assinaturas | G13: VALDEVINO PEREIRA SANTOS | H13: 45722 | I13: 0.41666667 | J13: RUA Gumercindo Marota N 81. Bairro: Santo Amaro | K13: Joanópolis - SP | L13: =350+59.7 -> 409.7 | M13: ok | N13: CUMPRIDO | O13: Gunnar Alberto Quina | P13: 11 91263-6342 | Q13: =200+119.4 -> 319.4 | S13: SIM | T13: CUMPRIDO | U13: =Table_4[[#This Row],[VALOR]]-Table_4[[#This Row],[ CUSTO]] -> 90.3
B14: 45716 | D14: Aline Paixão / Coutinho e Zorzanelli | E14: 13 99777-5515 / 21 98612-3240 | F14: UNA - Presencial | G14: 0010744-17.2024.5.15.0084 | H14: 45723 | I14: 0.41666667 | J14: 4ª Vara do Trabalho | K14: São José dos Campos - SP | L14: 300 | N14: CUMPRIDO | O14: Helena do Amaral Olivar Simionelli | P14: 12 99108-0694 | Q14: 100 | S14: SIM | T14: CUMPRIDO | U14: =Table_4[[#This Row],[VALOR]]-Table_4[[#This Row],[ CUSTO]] -> 200
B15: 45716 | D15: Jessica | E15: 41 9685-0539 | F15: Coleta de Assinaturas | G15: MARIA NANCI RODRIGUES PINHEIRO | H15: 45726 | I15: 0.45833333 | J15: Av. Dom Luís, 807 – 20º e 21º andar, Meireles | K15: Fortaleza - CE | L15: =300+91.2 -> 391.2 | M15: ok | N15: CUMPRIDO | O15: Gabriela Sousa | P15: 85 8640-0693 | Q15: =80+91.6 -> 171.6 | S15: SIM | T15: CUMPRIDO | U15: =Table_4[[#This Row],[VALOR]]-Table_4[[#This Row],[ CUSTO]] -> 219.6
B16: 45716 | D16: Vivian Barbosa / Raquel Moreira | E16: 11 94569-1656 / 11 98450-5051 | F16: Inicial - Presencial | G16: 0011845-93.2024.5.15.0115 | H16: 45729 | I16: 0.55555556 | J16: 2ª Vara do Trabalho | K16: Presidente Prudente - SP | L16: 400 | N16: CUMPRIDO | O16: Janaina Joice de Sousa Lourenço | P16: 18 98143-5578 | Q16: 170 | S16: SIM | T16: CUMPRIDO | U16: =Table_4[[#This Row],[VALOR]]-Table_4[[#This Row],[ CUSTO]] -> 230
B17: 45716 | D17: Vivian Barbosa / Raquel Moreira | E17: 11 94569-1656 / 11 98450-5051 | F17: Inicial - Virtual | G17: 0012738-32.2024.5.15.0003 | H17: 45729 | I17: 0.33333333 | J17: 1ª Vara do Trabalho | K17: Sorocaba - SP | L17: 75 | N17: CUMPRIDO | O17: Priscilla Araújo | P17: 11 96379-9086 | S17: SIM | T17: CUMPRIDO | U17: =Table_4[[#This Row],[VALOR]]-Table_4[[#This Row],[ CUSTO]] -> 75
B18: 45716 | D18: Vinícius Silvério | E18: 41 9178-7396 | F18: Instrução - Presencial | G18: 0020887-16.2021.5.04.0007 | H18: 45736 | I18: 0.55555556 | J18: 7ª Vara do Trabalho | K18: Porto Alegre - RS | L18: 400 | N18: CUMPRIDO | O18: Marlon de Araújo Aita | P18: 51 8405-8197 | Q18: 120 | S18: SIM | T18: CUMPRIDO | U18: =Table_4[[#This Row],[VALOR]]-Table_4[[#This Row],[ CUSTO]] -> 280
B19: 45721 | D19: Sepulveda | E19: 19 99651-8840 | F19: UNA - Presencial | H19: 45722 | I19: 0.42708333 | J19: Vara do Trabalho | K19: Itatiba - SP | L19: 150 | N19: CUMPRIDO | O19: Natalia Kaori Toyoda | P19: 19 98109-8066 | Q19: 120 | S19: SIM | T19: CUMPRIDO | U19: =Table_4[[#This Row],[VALOR]]-Table_4[[#This Row],[ CUSTO]] -> 30
B20: 45722 | D20: Thiago Coriolano | E20: 11 98775-8123 | F20: Audiência | H20: 45723 | I20: 0.35416667 | J20: 2ª | K20: Santo André - SP | L20: 200 | N20: CUMPRIDO | O20: Aureni | P20: 11 99896-9511 | Q20: 70 | R20: desv | S20: SIM | T20: CUMPRIDO | U20: =Table_4[[#This Row],[VALOR]]-Table_4[[#This Row],[ CUSTO]] -> 130
B21: 45722 | D21: Sepulveda | E21: 19 99651-8840 | F21: UNA - Presencial | H21: 45726 | I21: 0.64583333 | J21: 1ª Vara do Trabalho | K21: Osasco - SP | L21: 150 | N21: CUMPRIDO | O21: Joao Tomaz da Silva | P21: 11 97377-8980 | Q21: 70 | S21: SIM | T21: CUMPRIDO | U21: =Table_4[[#This Row],[VALOR]]-Table_4[[#This Row],[ CUSTO]] -> 80
B22: 45722 | D22: Anna - Luan | E22: 45 9928-1123 | F22: Conciliação - Presencial | G22: 1017839-60.2024.8.26.0008 | H22: 45733 | I22: 0.58333333 | J22: 1ª Juizado Especial Cível de Tatuapé | K22: São Paulo - SP | L22: 120 | N22: CUMPRIDO | O22: Leandro Ribeiro Lima | P22: 19 98420-0002 | Q22: 50 | S22: SIM | T22: CUMPRIDO | U22: =Table_4[[#This Row],[VALOR]]-Table_4[[#This Row],[ CUSTO]] -> 70
B23: 45722 | D23: LACOSTA ADVOGADOS | E23: 21 95922-4000 / 11 91039-6920 | F23: Instrução - Presencial | H23: 45737 | I23: 0.60416667 | J23: 90ª da Barra Funda | K23: São Paulo - SP | L23: 150 | N23: CUMPRIDO | O23: Joao Tomaz da Silva | P23: 11 97377-8980 | Q23: 70 | S23: SIM | T23: CUMPRIDO | U23: =Table_4[[#This Row],[VALOR]]-Table_4[[#This Row],[ CUSTO]] -> 80
B24: 45723 | D24: Thiago Coriolano | E24: 11 98775-8123 | F24: Audiência | H24: 45723 | I24: 0.38541667 | J24: Virtual | L24: 170 | N24: CUMPRIDO | O24: Priscilla Araújo | P24: 11 96379-9086 | Q24: 50 | S24: SIM | T24: CUMPRIDO | U24: =Table_4[[#This Row],[VALOR]]-Table_4[[#This Row],[ CUSTO]] -> 120
B25: 45723 | D25: Beça e Coussirat | E25: 11 97678-8835 | F25: Audiência | H25: 45726 | I25: 0.37638889 | J25: 1ª Vara do Trabalho | K25: Rio de Janeiro - RJ | L25: 150 | N25: CUMPRIDO | O25: Luana Martha | P25: 21 99499-9021 | Q25: 50 | S25: SIM | T25: CUMPRIDO | U25: =Table_4[[#This Row],[VALOR]]-Table_4[[#This Row],[ CUSTO]] -> 100
B26: 45723 | D26: Jessica | E26: 41 9685-0539 | F26: Coleta de Assinaturas | G26: MARIA JOSEFA PEREIRA LIMA | H26: 45726 | I26: 0.41666667 | J26: Filial Barra Funda | K26: São Paulo - SP | L26: 300 | M26: ok | N26: CUMPRIDO | O26: Arlindo Felipe Jr | P26: 11 99635-2611 | Q26: 50 | S26: SIM | T26: CUMPRIDO | U26: =Table_4[[#This Row],[VALOR]]-Table_4[[#This Row],[ CUSTO]] -> 250
B27: 45723 | D27: LACOSTA ADVOGADOS | E27: 21 95922-4000 / 11 91039-6920 | F27: Audiência | H27: 45727 | I27: 0.38541667 | J27: 67ª Vara do Trabalho da Barra Funda | K27: São Paulo - SP | L27: 150 | N27: CUMPRIDO | O27: Joao Tomaz da Silva | P27: 11 97377-8980 | Q27: 70 | S27: SIM | T27: CUMPRIDO | U27: =Table_4[[#This Row],[VALOR]]-Table_4[[#This Row],[ CUSTO]] -> 80
B28: 45723 | D28: JH Gomes Advocacia | E28: 11 98492-3401 | F28: Audiência | G28: 1002117-53.2024.5.02.0606 | H28: 45729 | I28: 0.375 | J28: 6ª Vara do Trabalho da Zona Leste | K28: São Paulo - SP | L28: 150 | N28: CUMPRIDO | O28: Calebe Fernandes da Silva Araújo | P28: 91 8418-4224 | Q28: 50 | R28: desv | S28: SIM | T28: CUMPRIDO | U28: =Table_4[[#This Row],[VALOR]]-Table_4[[#This Row],[ CUSTO]] -> 100
B29: 45726 | D29: Diego Carrara Palandrani | E29: 44 9815-1208 | F29: UNA - Presencial | G29: 1002403-59.2024.5.02.0241 | H29: 45727 | I29: 0.45833333 | J29: 1ª Vara do Trabalho | K29: Cotia - SP | L29: 170 | N29: CUMPRIDO | O29: Andreia Arantes | P29: 11 94736-8565 | Q29: 80 | S29: SIM | T29: CUMPRIDO | U29: =Table_4[[#This Row],[VALOR]]-Table_4[[#This Row],[ CUSTO]] -> 90
B30: 45726 | D30: Jessica | E30: 41 9685-0539 | F30: Coleta de Assinaturas | G30: Daniela Maia Alves | H30: 45727 | I30: 0.41666667 | J30: Rua Dr Campos Jr, 40, Centro. Próximo da praça Tiradentes | K30: Sete Lagoas - MG | L30: =300+74.1 -> 374.1 | M30: ok | N30: CUMPRIDO | O30: Barbara Moreira | P30: 31 9545-2147 | Q30: =50+74.1 -> 124.1 | S30: SIM | T30: CUMPRIDO | U30: =Table_4[[#This Row],[VALOR]]-Table_4[[#This Row],[ CUSTO]] -> 250
B31: 45726 | D31: Sepulveda | E31: 19 99651-8840 | F31: UNA - Presencial | H31: 45729 | I31: 0.45833333 | J31: 5ª Vara do Trabalho | K31: Osasco - SP | L31: 150 | N31: CUMPRIDO | O31: Regiane Alves | P31: 11 97609-6392 | Q31: 70 | S31: SIM | T31: CUMPRIDO | U31: =Table_4[[#This Row],[VALOR]]-Table_4[[#This Row],[ CUSTO]] -> 80
B32: 45726 | D32: Sepulveda | E32: 19 99651-8840 | F32: Acompanhamento de Perícia | H32: 45730 | I32: 0.54166667 | J32: Rua Coronel Mursa, 56 – Brás | K32: São Paulo - SP | L32: 150 | N32: CUMPRIDO | O32: Arlindo Felipe Jr | P32: 11 99635-2611 | Q32: 50 | S32: SIM | T32: CUMPRIDO | U32: =Table_4[[#This Row],[VALOR]]-Table_4[[#This Row],[ CUSTO]] -> 100
B33: 45727 | D33: Thiago Coriolano | E33: 11 98775-8123 | F33: Audiência | H33: 45727 | I33: 0.625 | J33: Procon | K33: Suzano - SP | L33: 200 | N33: CUMPRIDO | O33: Bianca Mota | P33: 11 97068-3345 | Q33: 70 | S33: SIM | T33: CUMPRIDO | U33: =Table_4[[#This Row],[VALOR]]-Table_4[[#This Row],[ CUSTO]] -> 130
B34: 45727 | D34: Bruno Magalhães | E34: 62 9166-2415 | F34: Audiência | H34: 45728 | I34: 0.41666667 | J34: 55ª Vara do Trabalho | K34: Rio de Janeiro - RJ | L34: 400 | N34: CUMPRIDO | O34: Catharine Rosa Cervino | P34: 21 97127-0834 | Q34: 70 | S34: SIM | T34: CUMPRIDO | U34: =Table_4[[#This Row],[VALOR]]-Table_4[[#This Row],[ CUSTO]] -> 330
B35: 45727 | D35: Jessica | E35: 41 9685-0539 | F35: Coleta de Assinaturas | G35: Marcos Roberto Cortes | H35: 45728 | I35: 0.4375 | J35: Rua Mexico, 31, sala 703, Centro | K35: Rio de Janeiro - RJ | L35: =300+36.8 -> 336.8 | M35: ok | N35: CUMPRIDO | O35: Wesley Severino Mattos | P35: 21 98179-8221 | Q35: =100+36.8 -> 136.8 | S35: SIM | T35: CUMPRIDO | U35: =Table_4[[#This Row],[VALOR]]-Table_4[[#This Row],[ CUSTO]] -> 200
B36: 45727 | D36: Jessica | E36: 41 9685-0539 | F36: Coleta de Assinaturas | G36: ZORAIDE GOMES CARVALHO DE SABOYA | H36: 45728 | I36: 0.41666667 | J36: Rua Padre Carapuceiro, 858 Centro Empresarial Queiroz Galvão, Torre Cícero Dias 7° andar sala 706 | K36: Recife -PE | L36: =300+92 -> 392 | M36: ok | N36: CUMPRIDO | O36: Rafael Vasconcelos Dutra | P36: 81 8452-1092 | Q36: =50+92 -> 142 | S36: SIM | T36: CUMPRIDO | U36: =Table_4[[#This Row],[VALOR]]-Table_4[[#This Row],[ CUSTO]] -> 250
B37: 45727 | D37: LACOSTA ADVOGADOS | E37: 21 95922-4000 / 11 91039-6920 | F37: Audiência | G37: 1001197-82.2024.5.02.0411 | H37: 45729 | I37: 0.54166667 | J37: Vara do Trabalho | K37: Ribeirão Pires - SP | L37: 200 | N37: CUMPRIDO | O37: Roberta Senne Hidalgo | P37: 11 98278-5283 | Q37: 100 | S37: SIM | T37: CUMPRIDO | U37: =Table_4[[#This Row],[VALOR]]-Table_4[[#This Row],[ CUSTO]] -> 100
B38: 45727 | D38: Andre Oliveira | E38: 19 98127-4386 | F38: UNA - Presencial | G38: 1000178-62.2025.5.02.0716 | H38: 45730 | I38: 0.38194444 | J38: 16ª Vara do Trabalho da Zona Sul | K38: São Paulo - SP | L38: 200 | M38: ok | N38: CUMPRIDO | O38: Elisangela ES - SOLUÇÕES JURÍDICAS | P38: 11 93067-5163 | Q38: 80 | S38: SIM | T38: CUMPRIDO | U38: =Table_4[[#This Row],[VALOR]]-Table_4[[#This Row],[ CUSTO]] -> 120
B39: 45728 | D39: Thiago Coriolano | E39: 11 98775-8123 | F39: Audiência | H39: 45729 | I39: 0.38541667 | J39: 1ª Vara do Trabalho | K39: Suzano - SP | L39: 200 | N39: CUMPRIDO | O39: Thais Pecin | P39: 11 97496-7395 | Q39: 90 | R39: desv | S39: SIM | T39: CUMPRIDO | U39: =Table_4[[#This Row],[VALOR]]-Table_4[[#This Row],[ CUSTO]] -> 110
B40: 45728 | D40: Dayana Reis | E40: 11 94772-0646 | F40: Conciliação - Presencial | G40: 0801005-10.2025.8.19.0045 | H40: 45729 | I40: 0.65277778 | J40: Juizado Especial Cível | K40: Resende - RJ | L40: 250 | N40: CUMPRIDO | O40: Igor Ferreira | P40: 24 99981-3333 | Q40: 150 | S40: SIM | T40: CUMPRIDO | U40: =Table_4[[#This Row],[VALOR]]-Table_4[[#This Row],[ CUSTO]] -> 100
B41: 45728 | D41: Thulyo Augustto | E41: 62 9683-9870 | F41: Audiência | G41: 0000087-39.2025.5.08.0128 | H41: 45729 | I41: 0.39583333 | J41: 3ª Vara do Trabalho | K41: Marabá - PA | L41: 350 | N41: CUMPRIDO | O41: Cinthia Veloso Alho Igreja | P41: 94 9233-5899 | Q41: 150 | S41: SIM | T41: CUMPRIDO | U41: =Table_4[[#This Row],[VALOR]]-Table_4[[#This Row],[ CUSTO]] -> 200
B42: 45728 | D42: Jessica | E42: 41 9685-0539 | F42: Coleta de Assinaturas | G42: RUY ALVES DE PAIVA | H42: 45729 | I42: 0.41666667 | J42: Rua Via Acesso Dois, nº 64, casa, Condomínio residencial Terra Nova | K42: Uberaba - MG | L42: =300+74.1 -> 374.1 | M42: ok | N42: CUMPRIDO | O42: Ana Guimarães | P42: 34 9159-6726 | Q42: =100+74.1 -> 174.1 | R42: desv | S42: SIM | T42: CUMPRIDO | U42: =Table_4[[#This Row],[VALOR]]-Table_4[[#This Row],[ CUSTO]] -> 200
...

Sheet ABRIL
B2: CONTROLE DE DILIGÊNCIAS
B4: SOLICITAÇÃO | C4: Nº. DOC9 | D4: SOLICITANTE | E4: TEL. | F4: TIPO DE DILIGÊNCIA | G4: Processo | H4: DATA | I4: HORA | J4: LOCAL | K4: Cidade - UF | L4: VALOR | M4: DATA PAG | N4: PAGAM. | O4: CONTRATADO | P4: TEL. 2 | Q4: CUSTO | R4: PRAZO | S4: PAGO | T4: STATUS | U4: LUCRO
B5: 45729 | D5: Andre Oliveira | E5: 19 98127-4386 | F5: Audiência | H5: 45748 | I5: 0.63194444 | J5: 3ª Vara do Trabalho | K5: Santos - SP | L5: 300 | M5: ok | N5: CUMPRIDO | O5: IRB - Isabelle | P5: 13 98804-4390 | Q5: 130 | S5: SIM | T5: CUMPRIDO | U5: =Table_5[[#This Row],[VALOR]]-Table_5[[#This Row],[ CUSTO]] -> 170
B6: 45730 | D6: Marcos Piva | E6: 11 96608-7561 | F6: Audiência | H6: 45748 | I6: 0.38194444 | J6: 6ª Vara do Trabalho | K6: Santos - SP | L6: 300 | M6: ok | N6: CUMPRIDO | O6: IRB - Isabelle | P6: 13 98804-4390 | Q6: 130 | S6: SIM | T6: CUMPRIDO | U6: =Table_5[[#This Row],[VALOR]]-Table_5[[#This Row],[ CUSTO]] -> 170
B7: 45740 | D7: LACOSTA ADVOGADOS | E7: 21 95922-4000 / 11 91039-6920 | F7: Advogado | H7: 45748 | I7: 0.41666667 | J7: 79ª Vara do Trabalho da Barra Funda | K7: São Paulo - SP | L7: 150 | M7: ok | N7: CUMPRIDO | O7: Laura Mautone | P7: 11 99305-2938 | Q7: 70 | R7: ok | S7: SIM | T7: CUMPRIDO | U7: =Table_5[[#This Row],[VALOR]]-Table_5[[#This Row],[ CUSTO]] -> 80
B8: 45741 | D8: Grace Bordalo | E8: 16 98822-1551 | F8: Sustentação Oral | H8: 45748 | J8: STJ | K8: Virtual | L8: 800 | N8: CUMPRIDO | O8: Patrícia Aparecida Carneiro | P8: 11 98265-6766 | Q8: 400 | R8: ok | S8: SIM | T8: CUMPRIDO | U8: =Table_5[[#This Row],[VALOR]]-Table_5[[#This Row],[ CUSTO]] -> 400
B9: 45742 | D9: Jessica | E9: 41 9685-0539 | F9: Coleta de Assinaturas | G9: JOSE VIANA LIMA | H9: 45748 | I9: 0.45833333 | J9: Filial da Barra Funda | K9: São Paulo - SP | L9: 300 | M9: ok | N9: CUMPRIDO | O9: Lucas Dias Soares | P9: 11 98307-6405 | Q9: 60 | R9: ok | S9: SIM | T9: CUMPRIDO | U9: =Table_5[[#This Row],[VALOR]]-Table_5[[#This Row],[ CUSTO]] -> 240
B10: 45743 | D10: Salem Advogados | E10: 11 95605-9699 | F10: Inicial - Virtual | G10: 0011900-98.2024.5.15.0097 | H10: 45748 | I10: 0.56944444 | J10: 4ª Vara do Trabalho | K10: Jundiaí - SP | N10: CUMPRIDO | O10: Joao Tomaz da Silva | P10: 11 97377-8980 | Q10: 40 | R10: ok | S10: SIM | T10: CUMPRIDO | U10: =Table_5[[#This Row],[VALOR]]-Table_5[[#This Row],[ CUSTO]] -> -40
B11: 45744 | D11: Fett Advogados Bruna Ferracini | E11: 51 9184-8885 | F11: Instrução - Presencial | G11: 0000611-69.2024.5.12.0060 | H11: 45748 | I11: 0.63541667 | J11: 3ª Vara do Trabalho | K11: Lages - SC | L11: 300 | N11: CUMPRIDO | O11: Andréa Cristina da Rosa | P11: 49 8812-6119 | Q11: 230 | R11: ok | S11: SIM | T11: CUMPRIDO | U11: =Table_5[[#This Row],[VALOR]]-Table_5[[#This Row],[ CUSTO]] -> 70
B12: 45747 | D12: Marcos Piva | E12: 11 96608-7561 | F12: Audiência | H12: 45748 | I12: 0.34375 | J12: 43ª Vara do Trabalho da Barra Funda | K12: São Paulo - SP | L12: 150 | M12: ok | N12: CUMPRIDO | O12: Amanda Rodrigues | P12: 11 95960-2876 | Q12: 50 | S12: SIM | T12: CUMPRIDO | U12: =Table_5[[#This Row],[VALOR]]-Table_5[[#This Row],[ CUSTO]] -> 100
B13: 45747 | D13: Cristiano Aparecido | E13: 11 98519-3150 | F13: Audiência | H13: 45748 | I13: 0.48958333 | J13: Trabalho da Zona Sul | K13: São Paulo - SP | L13: 120 | N13: CUMPRIDO | O13: Larissa Queiroz | P13: 11 91477-2823 | Q13: 70 | R13: desv | S13: SIM | T13: CUMPRIDO | U13: =Table_5[[#This Row],[VALOR]]-Table_5[[#This Row],[ CUSTO]] -> 50
B14: 45748 | D14: Rodrigo Bezerra | E14: 11 99360-4364 | F14: Audiência | H14: 45748 | I14: 0.66666667 | J14: Vara Federal | K14: São Paulo - SP | L14: 150 | N14: CUMPRIDO | O14: Ivo Rodrigues da Silva | P14: 11 98904-9114 | Q14: 70 | R14: ok | S14: SIM | T14: CUMPRIDO | U14: =Table_5[[#This Row],[VALOR]]-Table_5[[#This Row],[ CUSTO]] -> 80
B15: 45740 | D15: LACOSTA ADVOGADOS | E15: 21 95922-4000 / 11 91039-6920 | F15: Advogado | H15: 45749 | I15: 0.35763889 | J15: Vara do Trabalho | K15: Caçapava - SP | L15: 150 | M15: ok | N15: CUMPRIDO | O15: Keroleyni Rabello de Moura | P15: 12 99687-7381 | Q15: 70 | S15: SIM | T15: CUMPRIDO | U15: =Table_5[[#This Row],[VALOR]]-Table_5[[#This Row],[ CUSTO]] -> 80
B16: 45744 | D16: Fett Advogados Bruna Ferracini | E16: 51 9184-8885 | F16: UNA Presencial | G16: 0021601-41.2024.5.04.0404 | H16: 45749 | I16: 0.60416667 | J16: 4ª Vara do Trabalho | K16: Caxias do Sul - RS | L16: 200 | N16: CUMPRIDO | O16: Aline Patrícia Leonarski de Jesus | P16: 54 9686-0227 | Q16: 100 | S16: SIM | T16: CUMPRIDO | U16: =Table_5[[#This Row],[VALOR]]-Table_5[[#This Row],[ CUSTO]] -> 100
B17: 45744 | D17: Fett Advogados Bruna Ferracini | E17: 51 9184-8885 | F17: UNA Presencial | G17: 0021746-64.2024.5.04.0512 | H17: 45749 | I17: 0.39583333 | J17: 2ª Vara do Trabalho | K17: Bento Gonçalves - RS | L17: 200 | N17: CUMPRIDO | O17: Carol Coelho Kern | P17: 54 9619-7803 | Q17: 100 | S17: SIM | T17: CUMPRIDO | U17: =Table_5[[#This Row],[VALOR]]-Table_5[[#This Row],[ CUSTO]] -> 100
B18: 45747 | D18: Thulyo Augustto | E18: 62 9683-9870 | F18: Instrução - Presencial | H18: 45749 | I18: 0.57638889 | J18: 11ª Vara do Trabalho | K18: Brasília - DF | L18: 250 | N18: CUMPRIDO | O18: Maria Nubia | P18: 61 8411-7957 | Q18: 70 | R18: desv | S18: SIM | T18: CUMPRIDO | U18: =Table_5[[#This Row],[VALOR]]-Table_5[[#This Row],[ CUSTO]] -> 180
B19: 45748 | D19: Jessica | E19: 41 9685-0539 | F19: Coleta de Assinaturas | G19: JOSE VIANA LIMA | H19: 45749 | I19: 0.33333333 | J19: Filial da Barra Funda | K19: São Paulo - SP | L19: =170+44.75 -> 214.75 | M19: ok | N19: CUMPRIDO | O19: Lucas Dias Soares | P19: 11 98307-6405 | Q19: =60+44.75 -> 104.75 | S19: SIM | T19: CUMPRIDO | U19: =Table_5[[#This Row],[VALOR]]-Table_5[[#This Row],[ CUSTO]] -> 110
B20: 45748 | D20: Thiago Coriolano | E20: 11 98775-8123 | F20: Audiência | H20: 45749 | I20: 0.41666667 | J20: Vara do Trabalho | K20: Atibaia - SP | L20: 250 | N20: CUMPRIDO | O20: Patricia Von Ah | P20: 19 99155-8565 | Q20: 100 | S20: SIM | T20: CUMPRIDO | U20: =Table_5[[#This Row],[VALOR]]-Table_5[[#This Row],[ CUSTO]] -> 150
B21: 45729 | D21: Andre Oliveira | E21: 19 98127-4386 | F21: Audiência | H21: 45750 | I21: 0.59027778 | J21: 4ª Vara do Trabalho | K21: Santo André - SP | N21: CUMPRIDO | O21: Elisangela ES - SOLUÇÕES JURÍDICAS | P21: 11 93067-5163 | Q21: 60 | S21: SIM | T21: CUMPRIDO | U21: =Table_5[[#This Row],[VALOR]]-Table_5[[#This Row],[ CUSTO]] -> -60
B22: 45729 | D22: Andre Oliveira | E22: 19 98127-4386 | F22: Audiência | H22: 45750 | I22: 0.59027778 | J22: 4ª Vara do Trabalho | K22: Santo André - SP | L22: 300 | N22: CUMPRIDO | O22: Joao Tomaz da Silva | P22: 11 97377-8980 | Q22: 70 | S22: SIM | T22: CUMPRIDO | U22: =Table_5[[#This Row],[VALOR]]-Table_5[[#This Row],[ CUSTO]] -> 230
B23: 45730 | D23: Marcos Piva | E23: 11 96608-7561 | F23: Audiência | H23: 45750 | I23: 0.58680556 | J23: 4ª Vara do Trabalho | K23: Santo André - SP | N23: CUMPRIDO | O23: Elisangela ES - SOLUÇÕES JURÍDICAS | P23: 11 93067-5163 | Q23: 60 | S23: SIM | T23: CUMPRIDO | U23: =Table_5[[#This Row],[VALOR]]-Table_5[[#This Row],[ CUSTO]] -> -60
B24: 45730 | D24: Marcos Piva | E24: 11 96608-7561 | F24: Audiência | H24: 45750 | I24: 0.58680556 | J24: 4ª Vara do Trabalho | K24: Santo André - SP | L24: 300 | N24: CUMPRIDO | O24: Joao Tomaz da Silva | P24: 11 97377-8980 | Q24: 70 | S24: SIM | T24: CUMPRIDO | U24: =Table_5[[#This Row],[VALOR]]-Table_5[[#This Row],[ CUSTO]] -> 230
B25: 45749 | D25: Jessica | E25: 41 9685-0539 | F25: Coleta de Assinaturas | G25: Manoel Sebastião | H25: 45750 | I25: 0.58333333 | J25: Sala da OAB | K25: Rolândia - PR | L25: =300+27 -> 327 | M25: ok | N25: CUMPRIDO | O25: Gabriel José Pereira de Souza | P25: 43 9636-6543 | Q25: =120+27 -> 147 | S25: SIM | T25: CUMPRIDO | U25: =Table_5[[#This Row],[VALOR]]-Table_5[[#This Row],[ CUSTO]] -> 180
B26: 45749 | D26: Jessica | E26: 41 9685-0539 | F26: Coleta de Assinaturas | G26: CLEUTON JOSE CAETANO | H26: 45750 | I26: 0.66666667 | J26: Rua do Petróleo N° 438, Bairro Centro | K26: Carolina - MA | L26: =500+121.5 -> 621.5 | M26: ok | N26: CUMPRIDO | O26: Gabriela Aranha Peres Rodrigues | P26: 99 8245-4625 | Q26: =150+121.5 -> 271.5 | S26: SIM | T26: CUMPRIDO | U26: =Table_5[[#This Row],[VALOR]]-Table_5[[#This Row],[ CUSTO]] -> 350
B27: 45743 | D27: Salem Advogados | E27: 11 95605-9699 | F27: UNA Presencial | G27: 1002493-27.2024.5.02.0610 | H27: 45751 | I27: 0.55555556 | J27: 10ª Vara do Trabalho da Zona Leste | K27: São Paulo - SP | L27: 150 | N27: CUMPRIDO | O27: Joao Tomaz da Silva | P27: 11 97377-8980 | Q27: 70 | S27: SIM | T27: CUMPRIDO | U27: =Table_5[[#This Row],[VALOR]]-Table_5[[#This Row],[ CUSTO]] -> 80
B28: 45751 | D28: LACOSTA ADVOGADOS | E28: 21 95922-4000 / 11 91039-6920 | F28: Advogado | H28: 45754 | I28: 0.625 | J28: 87ª Vara do Trabalho da Barra Funda | K28: São Paulo - SP | L28: 150 | N28: CUMPRIDO | O28: Amanda Pivott | P28: 11 94857-0549 | Q28: 70 | R28: 45792 | S28: SIM | T28: CUMPRIDO | U28: =Table_5[[#This Row],[VALOR]]-Table_5[[#This Row],[ CUSTO]] -> 80
B29: 45751 | D29: Thulyo Augustto | E29: 62 9683-9870 | F29: Instrução - Presencial | G29: 0000087-39.2025.5.08.0128 | H29: 45754 | I29: 0.35416667 | J29: 3ª Vara do Trabalho | K29: Marabá - PA | L29: 350 | N29: CUMPRIDO | O29: Cinthia Veloso | P29: 94 9233-5899 | Q29: 150 | S29: SIM | T29: CUMPRIDO | U29: =Table_5[[#This Row],[VALOR]]-Table_5[[#This Row],[ CUSTO]] -> 200
B30: 45751 | D30: Beatriz Aragão & Bernardo | E30: 85 3252-2939 - 85 8405-1478 | F30: Audiência | G30: 0000145-53.2025.5.05.0022 | H30: 45754 | I30: 0.37847222 | J30: 22ª Vara do Trabalho | K30: Salvador - BA | L30: 170 | N30: CUMPRIDO | O30: Isadora Lopes Onofre | P30: 71 8392-7455 | Q30: 70 | S30: SIM | T30: CUMPRIDO | U30: =Table_5[[#This Row],[VALOR]]-Table_5[[#This Row],[ CUSTO]] -> 100
B31: 45751 | D31: Beatriz Aragão & Bernardo | E31: 85 3252-2939 - 85 8405-1478 | F31: Audiência | G31: 0002484-89.2024.5.09.0092 | H31: 45754 | I31: 0.59722222 | J31: Vara do Trabalho | K31: Cianorte - PR | L31: 200 | N31: CUMPRIDO | O31: KAREN DA SILVA BELTRAME | P31: 44 9937-9842 | Q31: 100 | S31: SIM | T31: CUMPRIDO | U31: =Table_5[[#This Row],[VALOR]]-Table_5[[#This Row],[ CUSTO]] -> 100
B32: 45751 | D32: Jessica | E32: 41 9685-0539 | F32: Cópia | G32: 0001968-74.2003.4.05.8410 | H32: 45754 | I32: 0.5 | J32: 7ª Vara do JEF | K32: Natal - RN | L32: 300 | M32: ok | N32: CUMPRIDO | O32: Maria Luiza | P32: 84 9841-2493 | Q32: 40 | R32: desv | S32: SIM | T32: CUMPRIDO | U32: =Table_5[[#This Row],[VALOR]]-Table_5[[#This Row],[ CUSTO]] -> 260
B33: 45754 | D33: LACOSTA ADVOGADOS | E33: 21 95922-4000 / 11 91039-6920 | F33: Preposto | H33: 45754 | I33: 0.625 | J33: 87ª Vara do Trabalho da Barra Funda | K33: São Paulo - SP | L33: 120 | N33: CUMPRIDO | O33: Nizael De Oliveira | P33: 11 98714-8872 | Q33: 40 | S33: SIM | T33: CUMPRIDO | U33: =Table_5[[#This Row],[VALOR]]-Table_5[[#This Row],[ CUSTO]] -> 80
B34: 45730 | D34: Marcos Piva | E34: 11 96608-7561 | F34: Audiência | G34: 1000224-14.2025.5.02.0502 | H34: 45755 | I34: 0.44791667 | J34: 2ª Vara do Trabalho | K34: Taboão da Serra - SP | L34: 300 | M34: ok | N34: CUMPRIDO | O34: Elisangela ES - SOLUÇÕES JURÍDICAS | P34: 11 93067-5163 | Q34: 150 | S34: SIM | T34: CUMPRIDO | U34: =Table_5[[#This Row],[VALOR]]-Table_5[[#This Row],[ CUSTO]] -> 150
B35: 45742 | D35: Murilo Máximo | E35: 11 98224-3603 | F35: Instrução - Presencial | H35: 45755 | I35: 0.35416667 | J35: 1ª Vara do Trabalho | K35: Euclides da Cunha - BA | L35: 300 | N35: CUMPRIDO | O35: Renata Lima | P35: 71 9979-5567 | Q35: 150 | S35: SIM | T35: CUMPRIDO | U35: =Table_5[[#This Row],[VALOR]]-Table_5[[#This Row],[ CUSTO]] -> 150
B36: 45749 | D36: Eliana | E36: 11 99955-0733 | F36: Sustentação Oral | G36: 1028588-34.2023.8.26.0506 | H36: 45755 | I36: 0.58333333 | J36: 10ª Câmara Direito Privado | K36: São Paulo - SP | L36: 800 | N36: CUMPRIDO | O36: Patrícia Aparecida Carneiro | P36: 11 98265-6766 | Q36: 300 | S36: SIM | T36: CUMPRIDO | U36: =Table_5[[#This Row],[VALOR]]-Table_5[[#This Row],[ CUSTO]] -> 500
B37: 45751 | D37: Jessica | E37: 41 9685-0539 | F37: Coleta de Assinaturas | G37: JOAO TADEU VITAL | H37: 45755 | I37: 0.4375 | J37: Filial da Barra Funda | K37: São Paulo - SP | L37: =300+36.8 -> 336.8 | M37: ok | N37: CUMPRIDO | O37: Arlindo Felipe Jr | P37: 11 99635-2611 | Q37: =50+36.8 -> 86.8 | S37: SIM | T37: CUMPRIDO | U37: =Table_5[[#This Row],[VALOR]]-Table_5[[#This Row],[ CUSTO]] -> 250
B38: 45751 | D38: Sepulveda Advogados Associados | E38: 19 99651-8840 | F38: Acompanhamento de perícia | H38: 45755 | I38: 0.35416667 | J38: RUA MARECHAL RONDON, 1768, PEDREGULHO | K38: Salto - SP | L38: 150 | N38: CUMPRIDO | O38: Larissa Domenice Nunes | P38: 11 99863-4716 | Q38: 80 | S38: SIM | T38: CUMPRIDO | U38: =Table_5[[#This Row],[VALOR]]-Table_5[[#This Row],[ CUSTO]] -> 70
B39: 45740 | D39: LACOSTA ADVOGADOS | E39: 21 95922-4000 / 11 91039-6920 | F39: Advogado | H39: 45756 | I39: 0.36458333 | J39: 58ª Vara do Trabalho da Barra Funda | K39: São Paulo - SP | L39: 150 | N39: CUMPRIDO | O39: Joao Tomaz da Silva | P39: 11 97377-8980 | Q39: 70 | S39: SIM | T39: CUMPRIDO | U39: =Table_5[[#This Row],[VALOR]]-Table_5[[#This Row],[ CUSTO]] -> 80
B40: 45751 | D40: LACOSTA ADVOGADOS | E40: 21 95922-4000 / 11 91039-6920 | F40: Advogado | H40: 45756 | I40: 0.48958333 | J40: 1ª Vara do Trabalho | K40: Praia Grande - SP | L40: 150 | N40: CUMPRIDO | O40: IRB - Isabelle | P40: 13 98804-4390 | Q40: 130 | S40: SIM | T40: CUMPRIDO | U40: =Table_5[[#This Row],[VALOR]]-Table_5[[#This Row],[ CUSTO]] -> 20
B41: 45751 | D41: LACOSTA ADVOGADOS | E41: 21 95922-4000 / 11 91039-6920 | F41: Preposto | H41: 45756 | I41: 0.48958333 | J41: 1ª Vara do Trabalho | K41: Praia Grande - SP | L41: 130 | N41: CUMPRIDO | O41: IRB - Isabelle | P41: 13 98804-4390 | S41: SIM | T41: CUMPRIDO | U41: =Table_5[[#This Row],[VALOR]]-Table_5[[#This Row],[ CUSTO]] -> 130
B42: 45751 | D42: Sepulveda Advogados Associados | E42: 19 99651-8840 | F42: Acompanhamento de perícia | H42: 45756 | I42: 0.39583333 | J42: SARNI & OLIVEIRA CARVALHO CLINICA ODONTOLOGICA LTDA - Avenida Inocêncio Seráfico, 4522, Vila Dirce | K42: Carapicuíba - SP | L42: 150 | N42: CUMPRIDO | O42: Selma Olegário | P42: 11 98180-2548 | Q42: 80 | S42: SIM | T42: CUMPRIDO | U42: =Table_5[[#This Row],[VALOR]]-Table_5[[#This Row],[ CUSTO]] -> 70
...

Sheet MAIO
B2: CONTROLE DE DILIGÊNCIAS
